IntegrityError
sqlalchemy.exc.IntegrityError: (psycopg2.errors.ForeignKeyViolation) insert or update on table "story_tags" violates foreign key constraint "story_tags_story_id_fkey"
DETAIL:  Key (story_id)=(7) is not present in table "story".

[SQL: INSERT INTO story_tags (story_id, tag_id) VALUES (%(story_id)s, %(tag_id)s)]
[parameters: {'story_id': 7, 'tag_id': 5}]
(Background on this error at: https://sqlalche.me/e/20/gkpj)

Traceback (most recent call last)
File "/home/runner/workspace/.pythonlibs/lib/python3.11/site-packages/sqlalchemy/engine/base.py", line 1964, in _exec_single_context
self.dialect.do_execute(
^
File "/home/runner/workspace/.pythonlibs/lib/python3.11/site-packages/sqlalchemy/engine/default.py", line 942, in do_execute
cursor.execute(statement, parameters)
^^^^^^^^^^^^^^^^^^^^^^^^^^^^^^^^^^^^^
The above exception was the direct cause of the following exception:
File "/home/runner/workspace/.pythonlibs/lib/python3.11/site-packages/flask/app.py", line 1536, in __call__
return self.wsgi_app(environ, start_response)
       ^^^^^^^^^^^^^^^^^^^^^^^^^^^^^^^^^^^^^^
File "/home/runner/workspace/.pythonlibs/lib/python3.11/site-packages/flask/app.py", line 1514, in wsgi_app
response = self.handle_exception(e)
           ^^^^^^^^^^^^^^^^^^^^^^^^
File "/home/runner/workspace/.pythonlibs/lib/python3.11/site-packages/flask/app.py", line 1511, in wsgi_app
response = self.full_dispatch_request()
           ^^^^^^^^^^^^^^^^^^^^^^^^^^^^
File "/home/runner/workspace/.pythonlibs/lib/python3.11/site-packages/flask/app.py", line 919, in full_dispatch_request
rv = self.handle_user_exception(e)
     ^^^^^^^^^^^^^^^^^^^^^^^^^^^^^
File "/home/runner/workspace/.pythonlibs/lib/python3.11/site-packages/flask/app.py", line 917, in full_dispatch_request
rv = self.dispatch_request()
     ^^^^^^^^^^^^^^^^^^^^^^^
File "/home/runner/workspace/.pythonlibs/lib/python3.11/site-packages/flask/app.py", line 902, in dispatch_request
return self.ensure_sync(self.view_functions[rule.endpoint])(**view_args)  # type: ignore[no-any-return]
       ^^^^^^^^^^^^^^^^^^^^^^^^^^^^^^^^^^^^^^^^^^^^^^^^^^^^^^^^^^^^^^^^^
File "/home/runner/workspace/.pythonlibs/lib/python3.11/site-packages/flask_login/utils.py", line 290, in decorated_view
return current_app.ensure_sync(func)(*args, **kwargs)
       ^^^^^^^^^^^^^^^^^^^^^^^^^^^^^^^^^^^^^^^^^^^^^^
File "/home/runner/workspace/app.py", line 193, in submit_story
db.session.commit()
^^^^^^^^^^^^^^^^^^^
File "/home/runner/workspace/.pythonlibs/lib/python3.11/site-packages/sqlalchemy/orm/scoping.py", line 599, in commit
return self._proxied.commit()
       ^^^^^^^^^^^^^^^^^^^^^^
File "/home/runner/workspace/.pythonlibs/lib/python3.11/site-packages/sqlalchemy/orm/session.py", line 2032, in commit
trans.commit(_to_root=True)
^^^^^^^^^^^^^^^^^^^^^^^^^^^
File "<string>", line 2, in commit
File "/home/runner/workspace/.pythonlibs/lib/python3.11/site-packages/sqlalchemy/orm/state_changes.py", line 139, in _go
ret_value = fn(self, *arg, **kw)
            ^^^^^^^^^^^^^^^^^^^^
File "/home/runner/workspace/.pythonlibs/lib/python3.11/site-packages/sqlalchemy/orm/session.py", line 1313, in commit
self._prepare_impl()
^^^^^^^^^^^^^^^^^^^^
File "<string>", line 2, in _prepare_impl
File "/home/runner/workspace/.pythonlibs/lib/python3.11/site-packages/sqlalchemy/orm/state_changes.py", line 139, in _go
ret_value = fn(self, *arg, **kw)
            ^^^^^^^^^^^^^^^^^^^^
File "/home/runner/workspace/.pythonlibs/lib/python3.11/site-packages/sqlalchemy/orm/session.py", line 1288, in _prepare_impl
self.session.flush()
^^^^^^^^^^^^^^^^^^^^
File "/home/runner/workspace/.pythonlibs/lib/python3.11/site-packages/sqlalchemy/orm/session.py", line 4353, in flush
self._flush(objects)
^^^^^^^^^^^^^^^^^^^^
File "/home/runner/workspace/.pythonlibs/lib/python3.11/site-packages/sqlalchemy/orm/session.py", line 4488, in _flush
with util.safe_reraise():
^^^^^^^^^^^^^^^^^^^^^^^^^^^^^^^^^^^^^^^^^^^^^^^^^
File "/home/runner/workspace/.pythonlibs/lib/python3.11/site-packages/sqlalchemy/util/langhelpers.py", line 146, in __exit__
raise exc_value.with_traceback(exc_tb)
^^^^^^^^^^^^^^^^^^^^^^^^^^^^^^^^^^^^^^
File "/home/runner/workspace/.pythonlibs/lib/python3.11/site-packages/sqlalchemy/orm/session.py", line 4449, in _flush
flush_context.execute()
^^^^^^^^^^^^^^^^^^^^^^^
File "/home/runner/workspace/.pythonlibs/lib/python3.11/site-packages/sqlalchemy/orm/unitofwork.py", line 466, in execute
rec.execute(self)
^^^^^^^^^^^^^^^^^
File "/home/runner/workspace/.pythonlibs/lib/python3.11/site-packages/sqlalchemy/orm/unitofwork.py", line 591, in execute
self.dependency_processor.process_saves(uow, states)
^^^^^^^^^^^^^^^^^^^^^^^^^^^^^^^^^^^^^^^^^^^^^^^^^^^^
File "/home/runner/workspace/.pythonlibs/lib/python3.11/site-packages/sqlalchemy/orm/dependency.py", line 1197, in process_saves
self._run_crud(
^
File "/home/runner/workspace/.pythonlibs/lib/python3.11/site-packages/sqlalchemy/orm/dependency.py", line 1260, in _run_crud
connection.execute(statement, secondary_insert)
^^^^^^^^^^^^^^^^^^^^^^^^^^^^^^^^^^^^^^^^^^^^^^^
File "/home/runner/workspace/.pythonlibs/lib/python3.11/site-packages/sqlalchemy/engine/base.py", line 1416, in execute
return meth(
       
File "/home/runner/workspace/.pythonlibs/lib/python3.11/site-packages/sqlalchemy/sql/elements.py", line 515, in _execute_on_connection
return connection._execute_clauseelement(
       
File "/home/runner/workspace/.pythonlibs/lib/python3.11/site-packages/sqlalchemy/engine/base.py", line 1638, in _execute_clauseelement
ret = self._execute_context(
      
File "/home/runner/workspace/.pythonlibs/lib/python3.11/site-packages/sqlalchemy/engine/base.py", line 1843, in _execute_context
return self._exec_single_context(
       
File "/home/runner/workspace/.pythonlibs/lib/python3.11/site-packages/sqlalchemy/engine/base.py", line 1983, in _exec_single_context
self._handle_dbapi_exception(
^
File "/home/runner/workspace/.pythonlibs/lib/python3.11/site-packages/sqlalchemy/engine/base.py", line 2352, in _handle_dbapi_exception
raise sqlalchemy_exception.with_traceback(exc_info[2]) from e
^^^^^^^^^^^^^^^^^^^^^^^^^^^^^^^^^^^^^^^^^^^^^^^^^^^^^^^^^^^^^
File "/home/runner/workspace/.pythonlibs/lib/python3.11/site-packages/sqlalchemy/engine/base.py", line 1964, in _exec_single_context
self.dialect.do_execute(
^
File "/home/runner/workspace/.pythonlibs/lib/python3.11/site-packages/sqlalchemy/engine/default.py", line 942, in do_execute
cursor.execute(statement, parameters)
^^^^^^^^^^^^^^^^^^^^^^^^^^^^^^^^^^^^^
sqlalchemy.exc.IntegrityError: (psycopg2.errors.ForeignKeyViolation) insert or update on table "story_tags" violates foreign key constraint "story_tags_story_id_fkey"
DETAIL: Key (story_id)=(7) is not present in table "story".

[SQL: INSERT INTO story_tags (story_id, tag_id) VALUES (%(story_id)s, %(tag_id)s)]
[parameters: {'story_id': 7, 'tag_id': 5}]
(Background on this error at: https://sqlalche.me/e/20/gkpj)
The debugger caught an exception in your WSGI application. You can now look at the traceback which led to the error.
To switch between the interactive traceback and the plaintext one, you can click on the "Traceback" headline. From the text traceback you can also create a paste of it.